{"uuid": "6a79f684-3118-470c-92d5-653b1ec2cc81", "children": ["4c814ac2-840c-451b-bc80-e362b530c3e6"], "befores": [{"name": "come_back", "status": "passed", "start": 1681755788665, "stop": 1681755788665}], "afters": [{"name": "come_back::0", "status": "broken", "statusDetails": {"message": "urllib3.exceptions.MaxRetryError: HTTPConnectionPool(host='localhost', port=62997): Max retries exceeded with url: /session/40cbe2bca3fe45c41f7501e7cd1c20af/url (Caused by NewConnectionError('<urllib3.connection.HTTPConnection object at 0x10d19f110>: Failed to establish a new connection: [Errno 61] Connection refused'))\n", "trace": "  File \"/Library/Frameworks/Python.framework/Versions/3.11/lib/python3.11/site-packages/allure_commons/_allure.py\", line 221, in __call__\n    return self._fixture_function(*args, **kwargs)\n           ^^^^^^^^^^^^^^^^^^^^^^^^^^^^^^^^^^^^^^^\n  File \"/Library/Frameworks/Python.framework/Versions/3.11/lib/python3.11/site-packages/_pytest/fixtures.py\", line 918, in _teardown_yield_fixture\n    next(it)\n  File \"/Users/maksim/PycharmProjects/MyNewProject/finaly_project/conftest.py\", line 52, in come_back\n    get_website_base.get(LPC().URL_CURRENT)\n  File \"/Library/Frameworks/Python.framework/Versions/3.11/lib/python3.11/site-packages/selenium/webdriver/remote/webdriver.py\", line 449, in get\n    self.execute(Command.GET, {\"url\": url})\n  File \"/Library/Frameworks/Python.framework/Versions/3.11/lib/python3.11/site-packages/selenium/webdriver/remote/webdriver.py\", line 438, in execute\n    response = self.command_executor.execute(driver_command, params)\n               ^^^^^^^^^^^^^^^^^^^^^^^^^^^^^^^^^^^^^^^^^^^^^^^^^^^^^\n  File \"/Library/Frameworks/Python.framework/Versions/3.11/lib/python3.11/site-packages/selenium/webdriver/remote/remote_connection.py\", line 290, in execute\n    return self._request(command_info[0], url, body=data)\n           ^^^^^^^^^^^^^^^^^^^^^^^^^^^^^^^^^^^^^^^^^^^^^^\n  File \"/Library/Frameworks/Python.framework/Versions/3.11/lib/python3.11/site-packages/selenium/webdriver/remote/remote_connection.py\", line 311, in _request\n    response = self._conn.request(method, url, body=body, headers=headers)\n               ^^^^^^^^^^^^^^^^^^^^^^^^^^^^^^^^^^^^^^^^^^^^^^^^^^^^^^^^^^^\n  File \"/Library/Frameworks/Python.framework/Versions/3.11/lib/python3.11/site-packages/urllib3/request.py\", line 78, in request\n    return self.request_encode_body(\n           ^^^^^^^^^^^^^^^^^^^^^^^^^\n  File \"/Library/Frameworks/Python.framework/Versions/3.11/lib/python3.11/site-packages/urllib3/request.py\", line 170, in request_encode_body\n    return self.urlopen(method, url, **extra_kw)\n           ^^^^^^^^^^^^^^^^^^^^^^^^^^^^^^^^^^^^^\n  File \"/Library/Frameworks/Python.framework/Versions/3.11/lib/python3.11/site-packages/urllib3/poolmanager.py\", line 376, in urlopen\n    response = conn.urlopen(method, u.request_uri, **kw)\n               ^^^^^^^^^^^^^^^^^^^^^^^^^^^^^^^^^^^^^^^^^\n  File \"/Library/Frameworks/Python.framework/Versions/3.11/lib/python3.11/site-packages/urllib3/connectionpool.py\", line 815, in urlopen\n    return self.urlopen(\n           ^^^^^^^^^^^^^\n  File \"/Library/Frameworks/Python.framework/Versions/3.11/lib/python3.11/site-packages/urllib3/connectionpool.py\", line 815, in urlopen\n    return self.urlopen(\n           ^^^^^^^^^^^^^\n  File \"/Library/Frameworks/Python.framework/Versions/3.11/lib/python3.11/site-packages/urllib3/connectionpool.py\", line 815, in urlopen\n    return self.urlopen(\n           ^^^^^^^^^^^^^\n  File \"/Library/Frameworks/Python.framework/Versions/3.11/lib/python3.11/site-packages/urllib3/connectionpool.py\", line 787, in urlopen\n    retries = retries.increment(\n              ^^^^^^^^^^^^^^^^^^\n  File \"/Library/Frameworks/Python.framework/Versions/3.11/lib/python3.11/site-packages/urllib3/util/retry.py\", line 592, in increment\n    raise MaxRetryError(_pool, url, error or ResponseError(cause))\n"}, "start": 1681755808121, "stop": 1681755808132}], "start": 1681755788665, "stop": 1681755808132}